---
layout: single
title:  "예외처리"
excerpt: "예외처리"

categories: Java
tags:  Java

permalink: /categories/2023-12-29-예외처리/ # url

toc: true
toc_sticky: true

date: 2023-12-29
last_modified_at: 2023-12-30
---

# 예외처리 
# 예외란?
```
프로그램에 문제가 있는 것을 말하며, 예외로 인해 시스템 동작이 멈추는 것을 막는 것을 "예외처리'라고 한다.
Exception : Error는 개발자가 대처할 수 있음.
Error : Error는 개발자가 대처할 수 없음.

Exception -> Checked Exception : '예외처리'를 반드시 해야하는 경우(네트워크, 파일 시스템 등)
          -> Unchecekd Exception : '예외처리'를 개발자의 판단에 맞기는 경우(데이터 오류 등)

Exception 클래스
Exception 클래스 하위클래스로 NullPointerException, NumberFormatException 등이 있다.

Exception -> NullPointerException : 객체를 가리키지 않고 있는 레퍼런스를 이용할 때
          -> ArrayIndexOutOfBoundException : 배열에서 존재하지 않는 인덱스를 가리킬 때
          -> NumberFormatException : 숫자데이터에 문자데이터등을 넣었을 때
```
# try ~ catch
```
개발자가 예외처리하기 가장 쉽고, 많이 사용되는 방법이다.
try{
  예외가 발생할 수 있는 코드
}catch(Exception e){
  예외가 발생했을 때 처리할 코드
}
```

```Java
package pjtTest;

public class MainClass {
	public static void main(String[] args) {
		
		int i = 10;
		int j = 0;
		int r = 0;
		
		System.out.println("Exception BEFORE");
		
		try {
			r = i / j;
		} catch (Exception e) {
			e.printStackTrace();
			String msg = e.getMessage();
			System.out.println("msg : " + msg);
		}
		
		System.out.println("Exception AFTER");
	}
}
```
    Exception BEFORE
    java.lang.ArithmeticException: / by zero
    	at pjtTest.MainClass.main(MainClass.java:13)
    msg : / by zero
    Exception AFTER
    
# 다양한 예외처리
Exception 및 하위 클래스를 이용해서 예외처리를 다양하게 할 수 있다.

```Java
package pjtTest;

import java.util.ArrayList;
import java.util.InputMismatchException;
import java.util.Scanner;

public class MainClass {
	public static void main(String[] args) {
		
		Scanner scanner = new Scanner(System.in);
		int i, j;
		ArrayList<String> list = null;
		
		int[] iArr = {0, 1, 2, 3, 4};
		
		System.out.println("Exception BEFORE");
		
		try {
			System.out.println("input i : ");
			i = scanner.nextInt();
			System.out.println("input j : ");
			j = scanner.nextInt();
			
			System.out.println("i / j = " + (i / j));
			
			for(int k = 0; k < 5; k++) {
				System.out.println("iArr["+ k + "] : " + iArr[k]);
			}
			System.out.println("list.size() : " + list.size());
		} catch (InputMismatchException e) {
			e.printStackTrace();
		} catch (ArrayIndexOutOfBoundsException e) {
			e.printStackTrace();
		} catch(Exception e) {
			e.printStackTrace();
		}
		
		System.out.println("Exception AFTER");
	}
}
```
    Exception BEFORE
    input i : 
    10
    input j : 
    0
    java.lang.ArithmeticException: / by zero
    Exception AFTER	at pjtTest.MainClass.main(MainClass.java:24)

    
    Exception BEFORE
    input i : 
    10
    input j : 
    10
    i / j = 1
    iArr[0] : 0
    iArr[1] : 1
    iArr[2] : 2
    iArr[3] : 3
    iArr[4] : 4
    java.lang.NullPointerException
    Exception AFTER
    	at pjtTest.MainClass.main(MainClass.java:29)
     
# finally
예외 발생 여부에 상관없이 반드시 실행된다.

```Java
package pjtTest;

import java.util.ArrayList;
import java.util.InputMismatchException;
import java.util.Scanner;

public class MainClass {
	public static void main(String[] args) {
		
		Scanner scanner = new Scanner(System.in);
		int i, j;
		ArrayList<String> list = null;
		
		int[] iArr = {0, 1, 2, 3, 4};
		
		System.out.println("Exception BEFORE");
		
		try {
			System.out.println("input i : ");
			i = scanner.nextInt();
			System.out.println("input j : ");
			j = scanner.nextInt();
			
			System.out.println("i / j = " + (i / j));
			
			for(int k = 0; k < 5; k++) {
				System.out.println("iArr["+ k + "] : " + iArr[k]);
			}
			System.out.println("list.size() : " + list.size());
		} catch (InputMismatchException e) {
			e.printStackTrace();
		} catch (ArrayIndexOutOfBoundsException e) {
			e.printStackTrace();
		} catch(Exception e) {
			e.printStackTrace();
		} finally {
			System.out.println("예외 발생 여부에 상관없이 언제나 실행 됩니다.");
		}
		
		System.out.println("Exception AFTER");
	}
}
```
    Exception BEFORE
    input i : 
    10
    input j : 
    5
    i / j = 2
    iArr[0] : 0
    iArr[1] : 1
    iArr[2] : 2
    iArr[3] : 3
    iArr[4] : 4
    java.lang.NullPointerException
    예외 발생 여부에 상관없이 언제나 실행 됩니다.
    Exception AFTER
    	at pjtTest.MainClass.main(MainClass.java:29)
     
# throws
예외 발생 시 예외 처리를 직접 하지 않고 호출한 곳으로 넘긴다.

```Java
package pjtTest;

public class MainClass {
	public static void main(String[] args) {
		
		MainClass mainClass = new MainClass();
		
		try {
			mainClass.firstMethod();
		} catch (Exception e) {
			e.printStackTrace();
		}
		
	}
		public void firstMethod() throws Exception{
			secondMethod();
		}
		
		public void secondMethod() throws Exception{
			thirdMethod();
		}
		
		public void thirdMethod() throws Exception{
			System.out.println("10 / 0  = " + (10 / 0));
		}
	
}
```
    java.lang.ArithmeticException: / by zero
    	at pjtTest.MainClass.thirdMethod(MainClass.java:24)
    	at pjtTest.MainClass.secondMethod(MainClass.java:20)
    	at pjtTest.MainClass.firstMethod(MainClass.java:16)
    	at pjtTest.MainClass.main(MainClass.java:9)
